<?xml version="1.0" ?>
<sdf version="1.9">
  <model name="m5fly">
    <pose>0 0 0.3 0 0 0</pose>

    <link name="base_link">
      <gravity>false</gravity>
      <inertial>
        <mass>0.035</mass>
        <inertia>
          <ixx>0.00003</ixx><ixy>0</ixy><ixz>0</ixz>
          <iyy>0.00003</iyy><iyz>0</iyz>
          <izz>0.00006</izz>
        </inertia>
      </inertial>

      <visual name="body_visual">
        <geometry>
          <box><size>0.07 0.07 0.05</size></box>
        </geometry>
        <material>
          <ambient>0.0 0.0 0.8 1</ambient>
          <diffuse>0.0 0.0 1.0 1</diffuse>
          <specular>0.0 0.0 0.1 1</specular>
          <emissive>0.0 0.0 0.5 1</emissive>
        </material>
      </visual>

      <collision name="collision">
        <geometry>
          <box><size>0.07 0.07 0.02</size></box>
        </geometry>
        <surface>
          <bounce>
            <restitution_coefficient>1.0</restitution_coefficient>
            <threshold>0</threshold>
          </bounce>
          <contact>
            <ode><max_vel>100</max_vel><min_depth>0.001</min_depth></ode>
          </contact>
        </surface>
      </collision>

      <collision name="top_guard_collision">
        <pose>0 0 0.035 0 0 0</pose>
        <geometry>
          <box><size>0.09 0.09 0.002</size></box>
        </geometry>
        <surface>
          <friction>
            <ode><mu>0.0</mu><mu2>0.0</mu2></ode>
          </friction>
          <bounce>
            <restitution_coefficient>0.9</restitution_coefficient>
            <threshold>0.01</threshold>
          </bounce>
          <contact>
            <ode><max_vel>100</max_vel><min_depth>0.001</min_depth></ode>
          </contact>
        </surface>
      </collision>
    </link>

    <link name="rotor_0">
      <pose>0.025 -0.025 0.02 0 0 0</pose>
      <gravity>false</gravity>
      <inertial><mass>0.001</mass>
        <inertia><ixx>0.000001</ixx><iyy>0.000001</iyy><izz>0.000001</izz></inertia>
      </inertial>
      <visual name="rotor_0_visual">
        <geometry><cylinder><radius>0.02</radius><length>0.002</length></cylinder></geometry>
        <material><diffuse>0.2 0.2 0.2 0.3</diffuse></material>
      </visual>
    </link>
    <joint name="rotor_0_joint" type="revolute">
      <parent>base_link</parent><child>rotor_0</child>
      <axis><xyz>0 0 1</xyz><limit><lower>-1e16</lower><upper>1e16</upper></limit></axis>
    </joint>

    <link name="rotor_1">
      <pose>-0.025 -0.025 0.02 0 0 0</pose>
      <gravity>false</gravity>
      <inertial><mass>0.001</mass>
        <inertia><ixx>0.000001</ixx><iyy>0.000001</iyy><izz>0.000001</izz></inertia>
      </inertial>
      <visual name="rotor_1_visual">
        <geometry><cylinder><radius>0.02</radius><length>0.002</length></cylinder></geometry>
        <material><diffuse>0.2 0.2 0.2 0.3</diffuse></material>
      </visual>
    </link>
    <joint name="rotor_1_joint" type="revolute">
      <parent>base_link</parent><child>rotor_1</child>
      <axis><xyz>0 0 1</xyz><limit><lower>-1e16</lower><upper>1e16</upper></limit></axis>
    </joint>

    <link name="rotor_2">
      <pose>0.025 0.025 0.02 0 0 0</pose>
      <gravity>false</gravity>
      <inertial><mass>0.001</mass>
        <inertia><ixx>0.000001</ixx><iyy>0.000001</iyy><izz>0.000001</izz></inertia>
      </inertial>
      <visual name="rotor_2_visual">
        <geometry><cylinder><radius>0.02</radius><length>0.002</length></cylinder></geometry>
        <material><diffuse>0.2 0.2 0.2 0.3</diffuse></material>
      </visual>
    </link>
    <joint name="rotor_2_joint" type="revolute">
      <parent>base_link</parent><child>rotor_2</child>
      <axis><xyz>0 0 1</xyz><limit><lower>-1e16</lower><upper>1e16</upper></limit></axis>
    </joint>

    <link name="rotor_3">
      <pose>-0.025 0.025 0.02 0 0 0</pose>
      <gravity>false</gravity>
      <inertial><mass>0.001</mass>
        <inertia><ixx>0.000001</ixx><iyy>0.000001</iyy><izz>0.000001</izz></inertia>
      </inertial>
      <visual name="rotor_3_visual">
        <geometry><cylinder><radius>0.02</radius><length>0.002</length></cylinder></geometry>
        <material><diffuse>0.2 0.2 0.2 0.3</diffuse></material>
      </visual>
    </link>
    <joint name="rotor_3_joint" type="revolute">
      <parent>base_link</parent><child>rotor_3</child>
      <axis><xyz>0 0 1</xyz><limit><lower>-1e16</lower><upper>1e16</upper></limit></axis>
    </joint>

    <!--
      VelocityControl: cmd_vel を速度として base_link に直接適用する。
      MulticopterVelocityControl は35g機体で発振するため使用しない。
    -->
    <plugin
      filename="ignition-gazebo-velocity-control-system"
      name="ignition::gazebo::systems::VelocityControl">
      <topic>/m5fly/cmd_vel</topic>
    </plugin>

  </model>
</sdf>
